<?xml version="1.0" encoding="utf-8" ?>

<robot name="arm2d2" xmlns:xacro="http://www.ros.org/wiki/xacro">
  <mujoco>
    <compiler meshdir="meshes" balanceinertia="true" discardvisual="false"/>
    <asset>
      <material name="grid" texture="grid" texrepeat="1 1" texuniform="true" reflectance=".2"/>
    </asset>
  </mujoco>

  <material name="silver">
    <color rgba="0.700 0.700 0.700 1.000" />
  </material>

  <link name="world"/>



  <link name="base_link">
    <inertial>
        <origin xyz="-2.154281413321998e-06 0.0035387814754625734 -0.0056639470834143136" rpy="0 0 0"/>
        <mass value="1.5479093566761954"/>
        <inertia ixx="0.010238" iyy="0.01139" izz="0.021617" ixy="-0.0" iyz="0.0" ixz="0.0"/>
    </inertial>
    <visual>
        <origin xyz="0 0 0.0025" rpy="0 0 0"/>
        <geometry>
        <mesh filename="package://arm2d2_v2_description/meshes/base_plate.stl" scale="0.001 0.001 0.001"/>
        </geometry>
        <material name="silver"/>
    </visual>
    <collision>
        <origin xyz="0 0 0.0025" rpy="0 0 0"/>
        <geometry>
        <mesh filename="package://arm2d2_v2_description/meshes/base_plate.stl" scale="0.001 0.001 0.001"/>
        </geometry>
    </collision>
  </link>

  <joint name="world_joint" type="fixed">
    <parent link="world"/>
    <child link="base_link"/>
    <origin xyz="0 0 0" rpy="0 0 0"/>
  </joint>

  <link name="base_connector">
      <inertial>
      <origin rpy="0 0 0" xyz="0.06861790086338357 -0.0835697992386399 0.07107579694115096"/>
      <mass value="4.519107238213137"/>
      <inertia ixx="0.059779" ixy="-0.0" ixz="0.0" iyy="0.062251" iyz="0.000956" izz="0.076317"/>
    </inertial>
    <visual>
      <origin rpy="0 0 0" xyz="0 0 0"/>
      <geometry>
        <box size="0.001 0.001 0.001"/>
      </geometry>
      <material name="silver"/>
    </visual>
    <collision>
      <origin rpy="0 0 0" xyz="0 0 0"/>
      <geometry>
        <box size="0.001 0.001 0.001"/>
      </geometry>
    </collision>
  </link>

  <joint name="base_connector_joint" type="fixed">
    <parent link="base_link"/>
    <child link="base_connector"/>
    <origin xyz="0 0 -0.005" rpy="1.57 0 0"/>
  </joint>


  <link name="link_1">
    <inertial>
      <origin xyz="-0.023234210000508494 0.032933361084236216 0.002920663644532681" rpy="0 0 0"/>
      <mass value="0.22666453646044638"/>
      <inertia ixx="0.000128" iyy="0.000201" izz="0.000231" ixy="3.1e-05" iyz="-5e-06" ixz="1.5e-05"/>
    </inertial>
    <visual>
      <origin xyz="-0.0851 -0.006604 0.0851" rpy="0 0 0"/>
      <geometry>
        <mesh filename="package://arm2d2_v2_description/meshes/link_1_1.stl" scale="0.001 0.001 0.001"/>
      </geometry>
      <material name="silver"/>
    </visual>
    <collision>
      <origin xyz="-0.0851 -0.006604 0.0851" rpy="0 0 0"/>
      <geometry>
        <mesh filename="package://arm2d2_v2_description/meshes/link_1_1.stl" scale="0.001 0.001 0.001"/>
      </geometry>
    </collision>
  </link>

  
  <joint name="joint_1" type="continuous">
    <origin xyz="0.085 0.006604 -0.085" rpy="0 -0.35  0"/>
    <parent link="base_connector"/>
    <child link="link_1"/>
    <axis xyz="0.0 -1.0 0.0"/>
    <limit effort="100" lower="3.14" upper="3.14" velocity="100"/>
  </joint>

  <link name="link_2">
    <inertial>
      <origin xyz="-0.004298579881610032 0.07240002211825339 0.016744309655985348" rpy="0 0 0"/>
      <mass value="0.2595123095947453"/>
      <inertia ixx="0.000561" iyy="0.000112" izz="0.000572" ixy="-6.1e-05" iyz="-9.9e-05" ixz="-9e-06"/>
    </inertial>
    <visual>
      <origin xyz="-0.090305 -0.046604 0.085785" rpy="0 0 0"/>
      <geometry>
        <mesh filename="package://arm2d2_v2_description/meshes/link_2_1.stl" scale="0.001 0.001 0.001"/>
      </geometry>
      <material name="silver"/>
    </visual>
    <collision>
      <origin xyz="-0.090305 -0.046604 0.085785" rpy="0 0 0"/>
      <geometry>
        <mesh filename="package://arm2d2_v2_description/meshes/link_2_1.stl" scale="0.001 0.001 0.001"/>
      </geometry>
    </collision>
  </link>

  <joint name="joint_2" type="revolute">
    <origin xyz="-0.005205 0.04 -0.000685" rpy="-0.436332 3.14 -0.03927"/>
    <limit lower="-1.919862" upper="1.396263" effort="100" velocity="100"/>
    <parent link="link_1" />
    <child link="link_2" />
    <axis xyz="-0.991445 -0.0 0.130526"/>
  </joint>

  <link name="link_3">
    <inertial>
      <origin xyz="-0.01624182942995088 -0.0066433309450394384 0.019077247172201647" rpy="0 0 0"/>
      <mass value="0.1304515658530355"/>
      <inertia ixx="5.4e-05" iyy="6.3e-05" izz="4.4e-05" ixy="-2e-06" iyz="8e-06" ixz="7e-06"/>
    </inertial>
    <visual>
      <origin xyz="-0.084346 -0.183285 0.054438" rpy="0 0 0"/>
      <geometry>
        <mesh filename="package://arm2d2_v2_description/meshes/link_3_1.stl" scale="0.001 0.001 0.001"/>
      </geometry>
      <material name="silver"/>
    </visual>
    <collision>
      <origin xyz="-0.084346 -0.183285 0.054438" rpy="0 0 0"/>
      <geometry>
        <mesh filename="package://arm2d2_v2_description/meshes/link_3_1.stl" scale="0.001 0.001 0.001"/>
      </geometry>
    </collision>
  </link>

  <joint name="joint_3" type="revolute">
    <origin xyz="-0.005959 0.136681 0.031347" rpy="-3.42078 0.23562 -0.03"/>
    <limit lower="-4.101524" upper="0.698132" effort="100" velocity="100"/>
    <parent link="link_2" />
    <child link="link_3" />
    <axis xyz="-0.991445 -0.0 0.130526"/>
  </joint>

  <link name="link_4">
    <inertial>
      <origin xyz="0.02326557503032635 -0.017807087000725114 0.04222851748201549" rpy="0 0 0"/>
      <mass value="0.21070496092935861"/>
      <inertia ixx="0.00028" iyy="0.000293" izz="0.000129" ixy="3.4e-05" iyz="8.1e-05" ixz="-8e-05"/>
    </inertial>
    <visual>
      <origin xyz="-0.059366 -0.168718 0.013574" rpy="0 0 0"/>
      <geometry>
        <mesh filename="package://arm2d2_v2_description/meshes/link_4_1.stl" scale="0.001 0.001 0.001"/>
      </geometry>
      <material name="silver"/>
    </visual>
    <collision>
      <origin xyz="-0.059366 -0.168718 0.013574" rpy="0 0 0"/>
      <geometry>
        <mesh filename="package://arm2d2_v2_description/meshes/link_4_1.stl" scale="0.001 0.001 0.001"/>
      </geometry>
    </collision>
  </link>

  <joint name="joint_4" type="continuous">
    <origin xyz="-0.02498 -0.014567 0.040864" rpy="0 0 0"/>
    <parent link="link_3" />
    <child link="link_4" />
    <axis xyz="0.121444 -0.366501 0.922458"/>
    <limit effort="100" lower="-3.14" upper="3.14" velocity="100"/>
  </joint>

  
  <link name="link_5">
    <inertial>
      <origin xyz="-0.02075508203374557 -0.023703571758186867 0.0028416884784955576" rpy="0 0 0"/>
      <mass value="0.15989560658307483"/>
      <inertia ixx="8.3e-05" iyy="5.8e-05" izz="9.9e-05" ixy="-1.8e-05" iyz="3e-06" ixz="2e-06"/>
    </inertial>
    <visual>
      <origin xyz="-0.091433 -0.131975 -0.076012" rpy="0 0 0"/>
      <geometry>
        <mesh filename="package://arm2d2_v2_description/meshes/link_5_1.stl" scale="0.001 0.001 0.001"/>
      </geometry>
      <material name="silver"/>
    </visual>
    <collision>
      <origin xyz="-0.091433 -0.131975 -0.076012" rpy="0 0 0"/>
      <geometry>
        <mesh filename="package://arm2d2_v2_description/meshes/link_5_1.stl" scale="0.001 0.001 0.001"/>
      </geometry>
    </collision>
  </link>

  <joint name="joint_5" type="revolute">
    <origin xyz="0.032067 -0.036743 0.089586" rpy="-2.38412 0.23562 0.1"/>
    <limit lower="-2.79" upper="0.524" effort="100" velocity="100"/>
    <parent link="link_4" />
    <child link="link_5" />
    <axis xyz="-0.991445 -0.0 0.130526"/>
  </joint>

  <link name="palm">
  <inertial>
    <origin xyz="0.061664701708749915 0.08137303558404387 0.08022062245839305" rpy="0 0 0"/>
    <mass value="0.013667083672765958"/>
    <inertia ixx="2e-06" iyy="3e-06" izz="2e-06" ixy="-0.0" iyz="-0.0" ixz="-0.0"/>
  </inertial>
  <visual>
    <origin xyz="0 0 0" rpy="0 0 0"/>
    <geometry>
      <mesh filename="package://arm2d2_v2_description/meshes/palm.stl" scale="0.001 0.001 0.001"/>
    </geometry>
    <material name="silver"/>
  </visual>
  <collision>
    <origin xyz="0 0 0" rpy="0 0 0"/>
    <geometry>
      <mesh filename="package://arm2d2_v2_description/meshes/palm.stl" scale="0.001 0.001 0.001"/>
    </geometry>
  </collision>
</link>

  <joint name="palm_joint" type="fixed">
    <origin xyz="-0.03 -0.041 0.0045" rpy="0 0 0"/>
    <parent link="link_5"/>
    <child link="palm"/>
  </joint>

  <link name="gripper_connector">
    <inertial>
      <origin rpy="0 0 0" xyz="2.9287E-10 -1.6472E-09 0.0091432"/>
      <mass value="0.013863"/>
      <inertia ixx="1.3596E-06" ixy="3.0585E-13" ixz="5.7102E-14" iyy="1.7157E-06" iyz="6.3369E-09" izz="2.4332E-06"/>
    </inertial>
  </link>

  <joint name="gripper_joint" type="revolute">
    <origin xyz="-0.03 -0.041 0.0045" rpy="0 0 0"/>
    <parent link="link_5"/>
    <child link="gripper_connector"/>
    <axis xyz="0 1 0"/>
    <limit lower="-3.1415" upper="3.1415" effort="100" velocity="100"/>
  </joint>

  <link name="actuator_1">
    <inertial>
      <origin xyz="0.005491083174233274 -0.03206197503178041 -0.0023745477788477826" rpy="0 0 0"/>
      <mass value="0.018363032655382763"/>
      <inertia ixx="8e-06" iyy="1e-06" izz="8e-06" ixy="0.0" iyz="0.0" ixz="-0.0"/>
    </inertial>
    <visual>
      <origin xyz="-0.008797 0.014908 -0.021091" rpy="0 0 0"/>
      <geometry>
        <mesh filename="package://arm2d2_v2_description/meshes/actuator_1_2.stl" scale="0.001 0.001 0.001"/>
      </geometry>
      <material name="silver"/>
    </visual>
    <collision>
      <origin xyz="-0.008797 0.014908 -0.021091" rpy="0 0 0"/>
      <geometry>
        <mesh filename="package://arm2d2_v2_description/meshes/actuator_1_2.stl" scale="0.001 0.001 0.001"/>
      </geometry>
    </collision>
  </link>

  <joint name="actuator_joint_1" type="revolute">
    <origin xyz="0.008797 -0.014908 0.021091" rpy="0 0 0"/>
    <parent link="palm"/>
    <child link="actuator_1"/>
    <axis xyz="-0.792929 0.002094 0.609311"/>
    <limit upper="1.22173" lower="0.0" effort="100" velocity="100"/>
  </joint>

    <link name="actuator_2">
      <inertial>
        <origin xyz="-0.0048912825904506435 -0.03207131009530898 -0.003353552242169211" rpy="0 0 0"/>
        <mass value="0.018363032655382763"/>
        <inertia ixx="8e-06" iyy="1e-06" izz="8e-06" ixy="0.0" iyz="-0.0" ixz="0.0"/>
      </inertial>
      <visual>
        <origin xyz="-0.013822 0.015067 0.017999" rpy="0 0 0"/>
        <geometry>
          <mesh filename="package://arm2d2_v2_description/meshes/actuator_2_1.stl" scale="0.001 0.001 0.001"/>
        </geometry>
        <material name="silver"/>
      </visual>
      <collision>
        <origin xyz="-0.013822 0.015067 0.017999" rpy="0 0 0"/>
        <geometry>
          <mesh filename="package://arm2d2_v2_description/meshes/actuator_2_1.stl" scale="0.001 0.001 0.001"/>
        </geometry>
      </collision>
    </link>


    <joint name="actuator_joint_2" type="revolute">
      <origin xyz="0.013822 -0.015067 -0.017999" rpy="0 0 0"/>
      <parent link="palm"/>
      <child link="actuator_2"/>
      <axis xyz="0.924146 0.002094 0.382034"/>
      <limit upper="1.22173" lower="0.0" effort="100" velocity="100"/>
    </joint>

    <link name="actuator_3">
      <inertial>
        <origin xyz="-0.0005475032335578722 -0.03202939701353134 0.006126837510314051" rpy="0 0 0"/>
        <mass value="0.018363032655382763"/>
        <inertia ixx="8e-06" iyy="1e-06" izz="8e-06" ixy="-0.0" iyz="0.0" ixz="0.0"/>
      </inertial>
      <visual>
        <origin xyz="0.022563 0.015024 0.00279" rpy="0 0 0"/>
        <geometry>
          <mesh filename="package://arm2d2_v2_description/meshes/actuator_3_1.stl" scale="0.001 0.001 0.001"/>
        </geometry>
        <material name="silver"/>
      </visual>
      <collision>
        <origin xyz="0.022563 0.015024 0.00279" rpy="0 0 0"/>
        <geometry>
          <mesh filename="package://arm2d2_v2_description/meshes/actuator_3_1.stl" scale="0.001 0.001 0.001"/>
        </geometry>
      </collision>
    </link>


    <joint name="actuator_joint_3" type="revolute">
      <origin xyz="-0.022563 -0.015024 -0.00279" rpy="0 0 0"/>
      <parent link="palm"/>
      <child link="actuator_3"/>
      <axis xyz="-0.131217 -0.004189 -0.991345"/>
      <limit upper="1.22173" lower="0.0" effort="100" velocity="100"/>
    </joint>

</robot>
