<mujoco model="R1">
<include file="mujoco/finger_1_assets.xml"/>
<include file="mujoco/finger_2_assets.xml"/>
<include file="mujoco/finger_3_assets.xml"/>
<include file="mujoco/finger_4_assets.xml"/>
<worldbody>
    <body name="R1_link_1" pos="-0.1101 0.0551 0.007" euler="1.57 1.57 0">
      <inertial pos="0.000994556 0.0321926 0.0346314" quat="0.983573 -0.108607 0.0374803 0.139225" mass="0.04795" diaginertia="0.000146434 0.000143118 5.64483e-05"/>
      <joint name="R1_joint_1" armature="0.01" pos="0 0 0" axis="0 -1 0" /> <!-- range="-1.0472 3.14159" -->
      <geom solref=".004 1" pos="-0.0551 -0.00635 -0.1101" type="mesh" mesh="link_1"/>
      <body name="R1_link_2" pos="0.018 0.035617 0" euler="0.0698132 0 0"><!--euler="0.0698132 0 0"-->
        <inertial pos="-4.23295e-05 0.0492156 0.00307385" quat="0.5 0.5 -0.5 0.5" mass="0.0072516" diaginertia="9.6e-05 9.1e-05 2.6e-05"/>
        <joint name="R1_joint_2" pos="0 0 0" axis="-1 0 0" range="-2.5 2.5"/>
        <geom solref=".004 1" pos="-0.0731 -0.041967 -0.1101" type="mesh" mesh="link_2"/>
        <body name="R1_link_3" pos="-0.018 0.089 0" euler="0 1.663222557 0"><!--euler="0 1.663222557 0"-->
          <inertial pos="-1.38234e-05 0.0302244 0.0200511" quat="0.980785 -0.19509 0 0" mass="0.0010804" diaginertia="7.1e-05 6.69706e-05 3.30294e-05"/>
          <joint name="R1_joint_3" armature="0.01" pos="0 0 0" axis="0 1 0"/>
          <geom solref=".004 1" pos="-0.0551 -0.130967 -0.1101" type="mesh" mesh="link_3"/>
          <body name="R1_link_4" pos="0.018 0.036618 0" euler="-1.664346 0 0"><!--euler="-1.664346 0 0"-->
            <inertial pos="-4.23295e-05 0.0491281 0.00307385" quat="0.5 0.5 -0.5 0.5" mass="0.0872515" diaginertia="9.6e-05 9.1e-05 2.6e-05"/>
            <joint name="R1_joint_4" armature="0.005" pos="0 0 0" axis="-1 0 0" range="-3.41 0.0872665"/>
            <geom solref=".004 1" pos="-0.0731 -0.167585 -0.1101" type="mesh" mesh="link_4"/>
            <body name="R1_link_5" pos="-0.018 0.089 0" euler="0 -2.24346 0"><!--euler="0 -2.24346 0"-->
              <inertial pos="6.10956e-05 0.0293393 0.017904" quat="0.984034 -0.177983 0 0" mass="0.0774864" diaginertia="6.5e-05 6.07398e-05 3.02602e-05"/>
              <joint name="R1_joint_5" pos="0 0 0" axis="0 1 0"/>
              <geom solref=".004 1" pos="-0.0551 -0.256585 -0.1101" type="mesh" mesh="link_5"/>
              <body name="R1_link_6" pos="0.018 0.036617 0" euler="1.6281267 0 0"><!--euler="1.6281267 0 0"-->
                <inertial pos="6.94042e-10 0.0491711 0.00307282" quat="0.5 0.5 -0.5 0.5" mass="0.0870349" diaginertia="9.6e-05 9.1e-05 2.6e-05"/>
                <joint name="R1_joint_6" armature="1" pos="0 0 0" axis="-1 0 0" range="0 3.14"/>
                <geom solref=".004 1" pos="-0.0731 -0.293202 -0.1101" type="mesh" mesh="link_6"/>
                <body name="R1_gripper_base" pos="-0.018 0.0775 0">
                  <geom solref=".004 1" pos="-0.0551 -0.370702 -0.1101" type="mesh" mesh="gripper_base"/>
                  <joint name="R1_joint_7" armature="1" pos="0 0 0" axis="0 1 0"/>
                  <body name="R1_finger_1" pos="0.006125 0.0535 0.0235" euler="-0.17 0 0">
                    <inertial pos="-0.00864261 -0.0223486 0.0179735" quat="0.653281 0.270598 -0.270598 0.653281" mass="0.00589988" diaginertia="1.33333e-06 1.33333e-06 1.33333e-06"/>
                    <joint name="R1_gripper_joint_1" armature="0.01" pos="0 0 0" axis="0.999727 0.017623 0.01534" range="-1 0"/>
                    <include file="mujoco/R1_finger_1.xml"/>
                  </body>
                  <body name="R1_finger_2" pos="-0.0235 0.0535 0.006125" euler="0 0 -0.17">
                    <inertial pos="-0.0230751 0.00329087 0.0169449" quat="0 0.92388 0 0.382683" mass="0.00589981" diaginertia="1.33333e-06 1.33333e-06 1.33333e-06"/>
                    <joint name="R1_gripper_joint_2" armature="0.01" pos="0 0 0" axis="0 0 1.0" range="-1 0"/>
                    <include file="mujoco/R1_finger_2.xml"/>
                  </body>
                  <body name="R1_finger_3" pos="-0.006125 0.0535 -0.0235" euler="0.17 0 0">
                    <inertial pos="0.00809087 0.0234324 0.0168113" quat="0.653281 -0.270598 0.270598 0.653281" mass="0.00589994" diaginertia="1.33333e-06 1.33333e-06 1.33333e-06"/>
                    <joint name="R1_gripper_joint_3" armature="0.01" pos="0 0 0" axis="-1.0 0.0 0" range="-1 0"/>
                    <include file="mujoco/R1_finger_3.xml"/>
                  </body>
                  <body name="R1_finger_4" pos="0.0235 0.0535 -0.006125" euler="0 0 0.17">
                    <inertial pos="0.0225221 -0.00220606 0.017841" quat="0.92388 0 0.382683 0" mass="0.00589986" diaginertia="1.33333e-06 1.33333e-06 1.33333e-06"/>
                    <joint name="R1_gripper_joint_4" armature="0.01" pos="0 0 0" axis="0 0 -1.0" range="-1 0"/>
                    <include file="mujoco/R1_finger_4.xml"/>
                  </body>
                </body>
              </body>
            </body>
          </body>
        </body>
      </body>
    </body>
</worldbody>

  <contact>
    <exclude name="R1_j1_contact" body1="base_link" body2="R1_link_1"/>
    <exclude name="R1_j2_contact" body1="R1_link_1" body2="R1_link_2"/>
    <!-- without j2_base_contact j2 doesn't reach full range even though it is possible -->
    <exclude name="R1_j2_base_contact" body1="R1_link_2" body2="base_link"/>
    <exclude name="R1_j3_contact" body1="R1_link_2" body2="R1_link_3"/>
    <exclude name="R1_j4_contact" body1="R1_link_4" body2="R1_link_5"/>
    <exclude name="R1_j7_contact" body1="R1_link_6" body2="R1_gripper_base"/>
    <exclude name="R1_gj1_contact" body1="R1_gripper_base" body2="R1_finger_1"/>
    <exclude name="R1_gj2_contact" body1="R1_gripper_base" body2="R1_finger_2"/>
    <exclude name="R1_gj3_contact" body1="R1_gripper_base" body2="R1_finger_3"/>
    <exclude name="R1_gj4_contact" body1="R1_gripper_base" body2="R1_finger_4"/>
    <!--add more to ignore collision between baseplate gripper-->
    <exclude name="R1_baseplate_finger_1_contact" body1="base_link" body2="R1_finger_1"/>
    <exclude name="R1_baseplate_finger_2_contact" body1="base_link" body2="R1_finger_2"/>
    <exclude name="R1_baseplate_finger_3_contact" body1="base_link" body2="R1_finger_3"/>
    <exclude name="R1_baseplate_finger_4_contact" body1="base_link" body2="R1_finger_4"/>
    <exclude name="R1_gripper_mount_contact" body1="R1_gripper_base" body2="base_link"/>


    

  </contact>

  <actuator>
    <velocity name="R1_J1" joint="R1_joint_1" kv="2" gear="5 0 0 0 0 0"/> 
    <velocity name="R1_J2" joint="R1_joint_2" kv="2" gear="6 0 0 0 0 0"/>
    <velocity name="R1_J3" joint="R1_joint_3" kv="1" gear="1 0 0 0 0 0"/> 
    <velocity name="R1_J4" joint="R1_joint_4" kv="1" gear="6 0 0 0 0 0"/>
    <velocity name="R1_J5" joint="R1_joint_5" kv="1" gear="1 0 0 0 0 0"/>
    <velocity name="R1_J6" joint="R1_joint_6" kv="1" gear="2 0 0 0 0 0"/>
    <velocity name="R1_J7" joint="R1_joint_7" kv="1" gear="2 0 0 0 0 0"/>
    <velocity name="R1_GJ1" joint="R1_gripper_joint_1" kv="3" gear="6 0 0 0 0 0"/>
    <velocity name="R1_GJ2" joint="R1_gripper_joint_2" kv="3" gear="6 0 0 0 0 0"/>
    <velocity name="R1_GJ3" joint="R1_gripper_joint_3" kv="3" gear="6 0 0 0 0 0"/>
    <velocity name="R1_GJ4" joint="R1_gripper_joint_4" kv="3" gear="6 0 0 0 0 0"/>
  </actuator>

  <sensor>
    <jointpos name="R1_J1_encoder" joint="R1_joint_1" noise="0.001"/>
    <jointpos name="R1_J2_encoder" joint="R1_joint_2" noise="0.001"/>
    <jointpos name="R1_J3_encoder" joint="R1_joint_3" noise="0.001"/>
    <jointpos name="R1_J4_encoder" joint="R1_joint_4" noise="0.001"/>
    <jointpos name="R1_J5_encoder" joint="R1_joint_5" noise="0.001"/>
    <jointpos name="R1_J6_encoder" joint="R1_joint_6" noise="0.001"/>
    <jointpos name="R1_J7_encoder" joint="R1_joint_7" noise="0.001"/>
    <jointpos name="R1_GJ1_encoder" joint="R1_gripper_joint_1" noise="0.001"/>
    <jointpos name="R1_GJ2_encoder" joint="R1_gripper_joint_2" noise="0.001"/>
    <jointpos name="R1_GJ3_encoder" joint="R1_gripper_joint_3" noise="0.001"/>
    <jointpos name="R1_GJ4_encoder" joint="R1_gripper_joint_4" noise="0.001"/>
  </sensor>

</mujoco>