<mujoco model="v5_gripper">
  <worldbody>
    <body name="gripper_base">
      <geom type="mesh" contype="0" conaffinity="0" group="1" density="0" mesh="gripper_base"/>
      <geom type="mesh" mesh="gripper_base"/>
      <body name="finger_1" pos="0.005959 -0.022452 0.054853">
        <inertial pos="-0.00864261 -0.0223486 0.0179735" quat="0.653281 0.270598 -0.270598 0.653281" mass="0.00589988" diaginertia="1.33333e-06 1.33333e-06 1.33333e-06"/>
        <joint name="gripper_joint_1" armature="0.01" pos="0 0 0" axis="0.999727 0.017623 0.01534" range="-1 0"/>
        <geom pos="-0.005959 0.022452 -0.054853" type="mesh" contype="0" conaffinity="0" group="1" density="0" mesh="finger_1_1"/>
        <geom pos="-0.005959 0.022452 -0.054853" type="mesh" mesh="finger_1_1"/>
      </body>
      <body name="finger_4" pos="0.022822 0.00746 0.054188">
        <inertial pos="0.0225221 -0.00220606 0.017841" quat="0.92388 0 0.382683 0" mass="0.00589986" diaginertia="1.33333e-06 1.33333e-06 1.33333e-06"/>
        <joint name="gripper_joint_2" armature="0.01" pos="0 0 0" axis="-0.017134 0.999359 -0.031436" range="-1 0"/>
        <geom pos="-0.022822 -0.00746 -0.054188" type="mesh" contype="0" conaffinity="0" group="1" density="0" mesh="finger_4_1"/>
        <geom pos="-0.022822 -0.00746 -0.054188" type="mesh" mesh="finger_4_1"/>
      </body>
      <body name="finger_3" pos="-0.007093 0.024302 0.053188">
        <inertial pos="0.00809087 0.0234324 0.0168113" quat="0.653281 -0.270598 0.270598 0.653281" mass="0.00589994" diaginertia="1.33333e-06 1.33333e-06 1.33333e-06"/>
        <joint name="gripper_joint_3" armature="0.01" pos="0 0 0" axis="-0.999727 -0.017623 -0.01534" range="-1 0"/>
        <geom pos="0.007093 -0.024302 -0.053188" type="mesh" contype="0" conaffinity="0" group="1" density="0" mesh="finger_3_1"/>
        <geom pos="0.007093 -0.024302 -0.053188" type="mesh" mesh="finger_3_1"/>
      </body>
      <body name="finger_2" pos="-0.023955 -0.005611 0.053852">
        <inertial pos="-0.0230751 0.00329087 0.0169449" quat="0 0.92388 0 0.382683" mass="0.00589981" diaginertia="1.33333e-06 1.33333e-06 1.33333e-06"/>
        <joint name="gripper_joint_4" armature="0.01" pos="0 0 0" axis="0.017134 -0.999359 0.031436" range="-1 0"/>
        <geom pos="0.023955 0.005611 -0.053852" type="mesh" contype="0" conaffinity="0" group="1" density="0" mesh="finger_2_1"/>
        <geom pos="0.023955 0.005611 -0.053852" type="mesh" mesh="finger_2_1"/>
      </body>
    </body>
  </worldbody>
  <contact>
    <exclude name="gj1_contact" body1="gripper_base" body2="finger_1"/>
    <exclude name="gj2_contact" body1="gripper_base" body2="finger_2"/>
    <exclude name="gj3_contact" body1="gripper_base" body2="finger_3"/>
    <exclude name="gj4_contact" body1="gripper_base" body2="finger_4"/>
  </contact>

  <actuator>
    <velocity name="GJ1" joint="gripper_joint_1" kv="3" gear="6 0 0 0 0 0"/>
    <velocity name="GJ2" joint="gripper_joint_2" kv="3" gear="6 0 0 0 0 0"/>
    <velocity name="GJ3" joint="gripper_joint_3" kv="3" gear="6 0 0 0 0 0"/>
    <velocity name="GJ4" joint="gripper_joint_4" kv="3" gear="6 0 0 0 0 0"/>
  </actuator>
</mujoco>
