<?xml version="1.0" ?>
<robot name="arm2d2" xmlns:xacro="http://www.ros.org/wiki/xacro">

<material name="silver">
  <color rgba="0.700 0.700 0.700 1.000" />
</material>

<link name="world"/>

<link name="base_link">
  <inertial>
    <origin xyz="0.004501296079379289 0.011611289488489916 -0.0003795390518201785" rpy="0 0 0"/>
    <mass value="0.7941565726318868"/>
    <inertia ixx="0.005386" iyy="0.010606" izz="0.005746" ixy="-0.00012" iyz="0.000153" ixz="-0.001191"/>
  </inertial>
  <visual>
    <origin xyz="0 0 0" rpy="0 0 0"/>
    <geometry>
      <mesh filename="package://arm2d2_v3_description/meshes/base_link.stl" scale="0.01 0.01 0.01"/>
    </geometry>
    <material name="silver"/>
  </visual>
  <collision>
    <origin xyz="0 0 0" rpy="0 0 0"/>
    <geometry>
      <mesh filename="package://arm2d2_v3_description/meshes/base_link.stl" scale="0.01 0.01 0.01"/>
    </geometry>
  </collision>
</link>

<joint name="world_joint" type="fixed">
  <parent link="world"/>
  <child link="base_link"/>
  <origin xyz="0 0 0.1" rpy="1.57 0 0"/>
</joint>

<link name="link_1">
  <inertial>
    <origin xyz="0.0009290462769891011 0.0323589995171471 0.03303436243840866" rpy="0 0 0"/>
    <mass value="0.15567877825362636"/>
    <inertia ixx="0.000157" iyy="0.000149" izz="6.3e-05" ixy="-0.0" iyz="-1.8e-05" ixz="-5e-06"/>
  </inertial>
  <visual>
    <origin xyz="0.110082 -0.006606 0.055268" rpy="0 0 0"/>
    <geometry>
      <mesh filename="package://arm2d2_v3_description/meshes/link1_1.stl" scale="0.01 0.01 0.01"/>
    </geometry>
    <material name="silver"/>
  </visual>
  <collision>
    <origin xyz="0.110082 -0.006606 0.055268" rpy="0 0 0"/>
    <geometry>
      <mesh filename="package://arm2d2_v3_description/meshes/link1_1.stl" scale="0.01 0.01 0.01"/>
    </geometry>
  </collision>
</link>

<link name="link_2">
  <inertial>
    <origin xyz="2.200134078080007e-05 0.05737207658632189 0.009511520171388718" rpy="0 0 0"/>
    <mass value="0.11321174797267494"/>
    <inertia ixx="0.000125" iyy="4.4e-05" izz="0.00013" ixy="-0.0" iyz="-0.0" ixz="-0.0"/>
  </inertial>
  <visual>
    <origin xyz="0.110082 -0.042223 0.065268" rpy="0 0 0"/>
    <geometry>
      <mesh filename="package://arm2d2_v3_description/meshes/link2_1.stl" scale="0.01 0.01 0.01"/>
    </geometry>
    <material name="silver"/>
  </visual>
  <collision>
    <origin xyz="0.110082 -0.042223 0.065268" rpy="0 0 0"/>
    <geometry>
      <mesh filename="package://arm2d2_v3_description/meshes/link2_1.stl" scale="0.01 0.01 0.01"/>
    </geometry>
  </collision>
</link>

<link name="link_3">
  <inertial>
    <origin xyz="-9.204027404591253e-06 0.02804435596911231 0.008652381007916696" rpy="0 0 0"/>
    <mass value="0.1404930914377384"/>
    <inertia ixx="0.000123" iyy="0.000107" izz="5.9e-05" ixy="0.0" iyz="-1.9e-05" ixz="0.0"/>
  </inertial>
  <visual>
    <origin xyz="0.110082 -0.131723 0.055768" rpy="0 0 0"/>
    <geometry>
      <mesh filename="package://arm2d2_v3_description/meshes/link3_1.stl" scale="0.01 0.01 0.01"/>
    </geometry>
    <material name="silver"/>
  </visual>
  <collision>
    <origin xyz="0.110082 -0.131723 0.055768" rpy="0 0 0"/>
    <geometry>
      <mesh filename="package://arm2d2_v3_description/meshes/link3_1.stl" scale="0.01 0.01 0.01"/>
    </geometry>
  </collision>
</link>

<link name="link_4">
  <inertial>
    <origin xyz="2.3618679291084743e-05 0.05202027718928376 0.00950839991863061" rpy="0 0 0"/>
    <mass value="0.09419250470207502"/>
    <inertia ixx="0.0001" iyy="2.7e-05" izz="0.000106" ixy="-0.0" iyz="-0.0" ixz="0.0"/>
  </inertial>
  <visual>
    <origin xyz="0.110082 -0.167341 0.065768" rpy="0 0 0"/>
    <geometry>
      <mesh filename="package://arm2d2_v3_description/meshes/link4_1.stl" scale="0.01 0.01 0.01"/>
    </geometry>
    <material name="silver"/>
  </visual>
  <collision>
    <origin xyz="0.110082 -0.167341 0.065768" rpy="0 0 0"/>
    <geometry>
      <mesh filename="package://arm2d2_v3_description/meshes/link4_1.stl" scale="0.01 0.01 0.01"/>
    </geometry>
  </collision>
</link>

<link name="link_5">
  <inertial>
    <origin xyz="7.910862210346037e-05 0.03003098376590957 0.01590855403426706" rpy="0 0 0"/>
    <mass value="0.09348203833417927"/>
    <inertia ixx="7e-05" iyy="6e-05" izz="4.1e-05" ixy="-0.0" iyz="-1e-05" ixz="-0.0"/>
  </inertial>
  <visual>
    <origin xyz="0.110082 -0.256841 0.056268" rpy="0 0 0"/>
    <geometry>
      <mesh filename="package://arm2d2_v3_description/meshes/link5_1.stl" scale="0.01 0.01 0.01"/>
    </geometry>
    <material name="silver"/>
  </visual>
  <collision>
    <origin xyz="0.110082 -0.256841 0.056268" rpy="0 0 0"/>
    <geometry>
      <mesh filename="package://arm2d2_v3_description/meshes/link5_1.stl" scale="0.01 0.01 0.01"/>
    </geometry>
  </collision>
</link>

<link name="gripper">
  <inertial>
    <origin xyz="0.0005651763785821801 0.06065258242303184 0.01133988363017737" rpy="0 0 0"/>
    <mass value="0.09928638713059858"/>
    <inertia ixx="0.000172" iyy="3e-05" izz="0.000174" ixy="-3e-06" iyz="-1e-05" ixz="-1e-06"/>
  </inertial>
  <visual>
    <origin xyz="0.110082 -0.292458 0.066268" rpy="0 0 0"/>
    <geometry>
      <mesh filename="package://arm2d2_v3_description/meshes/gripper.stl" scale="0.01 0.01 0.01"/>
    </geometry>
    <material name="silver"/>
  </visual>
  <collision>
    <origin xyz="0.110082 -0.292458 0.066268" rpy="0 0 0"/>
    <geometry>
      <mesh filename="package://arm2d2_v3_description/meshes/gripper.stl" scale="0.01 0.01 0.01"/>
    </geometry>
  </collision>
</link>

<joint name="joint_1" type="revolute">
  <origin xyz="-0.110082 0.006606 -0.055268" rpy="0 0 0"/>
  <parent link="base_link"/>
  <child link="link_1"/>
  <axis xyz="0.0 1.0 -0.0"/>
  <limit upper="0.872665" lower="-3.141593" effort="100" velocity="100"/>
</joint>

<joint name="joint_2" type="revolute">
  <origin xyz="0.0 0.035617 -0.01" rpy="0 0 0"/>
  <parent link="link_1"/>
  <child link="link_2"/>
  <axis xyz="0.0 -0.0 -1.0"/>
  <limit upper="1.570796" lower="-1.570796" effort="100" velocity="100"/>
</joint>

<joint name="joint_3" type="continuous">
  <origin xyz="0.0 0.0895 0.0095" rpy="0 0 0"/>
  <parent link="link_2"/>
  <child link="link_3"/>
  <axis xyz="-0.0 -1.0 0.0"/>
</joint>

<joint name="joint_4" type="continuous">
  <origin xyz="0.0 0.035618 -0.01" rpy="0 0 0"/>
  <parent link="link_3"/>
  <child link="link_4"/>
  <axis xyz="0.0 -0.0 -1.0"/>
</joint>

<joint name="joint_5" type="continuous">
  <origin xyz="0.0 0.0895 0.0095" rpy="0 0 0"/>
  <parent link="link_4"/>
  <child link="link_5"/>
  <axis xyz="-0.0 -1.0 0.0"/>
</joint>

<joint name="joint_6" type="revolute">
  <origin xyz="0.0 0.035617 -0.01" rpy="0 0 0"/>
  <parent link="link_5"/>
  <child link="gripper"/>
  <axis xyz="0.0 -0.0 -1.0"/>
  <limit upper="1.919862" lower="-1.919862" effort="100" velocity="100"/>
</joint>

</robot>
