<mujoco model="arm2d2_v3">
  <visual>
    <headlight ambient="0 0 0" diffuse="0.3 0.3 0.3" specular="1 1 1"/>
    <quality shadowsize="8192"/>
  </visual>
  <compiler angle="radian" meshdir="../meshes/" autolimits="true"/>
  <option integrator="RK4" timestep="0.0001">
    <flag gravity="disable"/>
  </option>
  <size njmax="500" nconmax="100"/>
  <default/>
  <asset>
    <texture type="skybox" filefront="/home/cyborg/catkin_ws/src/daedalus/arm2d2_v3_description/meshes/simulation_assets/earth006000.png"
                           fileright="/home/cyborg/catkin_ws/src/daedalus/arm2d2_v3_description/meshes/simulation_assets/earth006001.png"
                           fileleft="/home/cyborg/catkin_ws/src/daedalus/arm2d2_v3_description/meshes/simulation_assets/earth006003.png"
                           fileup="/home/cyborg/catkin_ws/src/daedalus/arm2d2_v3_description/meshes/simulation_assets/earth006005.png"
                           filedown="/home/cyborg/catkin_ws/src/daedalus/arm2d2_v3_description/meshes/simulation_assets/earth006004.png"
                           fileback="/home/cyborg/catkin_ws/src/daedalus/arm2d2_v3_description/meshes/simulation_assets/earth006002.png"/>
    <mesh name="base_link" file="base_link.stl" scale="0.01 0.01 0.01"/>
    <mesh name="link1_1" file="link1_1.stl" scale="0.01 0.01 0.01"/>
    <mesh name="link2_1" file="link2_1.stl" scale="0.01 0.01 0.01"/>
    <mesh name="link3_1" file="link3_1.stl" scale="0.01 0.01 0.01"/>
    <mesh name="link4_1" file="link4_1.stl" scale="0.01 0.01 0.01"/>
    <mesh name="link5_1" file="link5_1.stl" scale="0.01 0.01 0.01"/>
    <mesh name="gripper" file="gripper.stl" scale="0.01 0.01 0.01"/>
    <mesh name="finger_2b" file="finger_2b.stl" scale="0.01 0.01 0.01"/>
    <mesh name="finger_2c" file="finger_2c.stl" scale="0.01 0.01 0.01"/>
    <mesh name="finger_1a" file="finger_1a.stl" scale="0.01 0.01 0.01"/>
    <mesh name="finger_1b" file="finger_1b.stl" scale="0.01 0.01 0.01"/>
    <mesh name="finger_1c" file="finger_1c.stl" scale="0.01 0.01 0.01"/>
    <mesh name="finger_3a" file="finger_3a.stl" scale="0.01 0.01 0.01"/>
    <mesh name="finger_3b" file="finger_3b.stl" scale="0.01 0.01 0.01"/>
    <mesh name="finger_3c" file="finger_3c.stl" scale="0.01 0.01 0.01"/>
    <mesh name="finger_2a" file="finger_2a.stl" scale="0.01 0.01 0.01"/>
    <mesh file="wrench.stl" scale=".0015 .0015 .0015"/>
  </asset>
  <worldbody>     
    <light pos=".4 .4 .5" dir="-2 -2 -1.5" diffuse="1 1 1"/>


    <body name="wrench" pos="-0.5 -0.2 0.2">
        <joint type="free"/>
        <geom type="mesh" mesh="wrench" euler="90 0 180" rgba="1 0 0 1"/>
    </body>

    <body name="cube" pos="-0.5 -0.2 0.5">
      <joint type="free"/>
      <geom type="box" size="0.025 0.025 0.025" rgba="1 0 0 1"/>
    </body>
    
    
    <body name="ball" pos="-0.025 -0.05 0.05">
      <joint type="free"/>
      <geom type="sphere" size="0.02" rgba="1 0 0 1"/>
    </body>
      
    <body name="base_link" pos="0 0 0.01" quat="0.707388 0.706825 0 0">
      <!--<geom pos="0 0 0.01" quat="0.707388 0.706825 0 0" type="mesh" contype="0" conaffinity="0" group="1" density="0" mesh="base_link"/>-->
      <geom type="mesh" contype="0" conaffinity="0" group="1" density="0" mesh="base_link"/>
    
      <body name="link1_1" pos="-0.110082 0.006606 -0.055268">
        <inertial pos="0.000929046 0.032359 0.0330344" quat="0.990044 -0.0956615 0.0346668 0.0972618" mass="0.155679" diaginertia="0.000157446 0.000152415 5.9139e-05"/>
        <joint name="joint_1" pos="0 0 0" axis="0 1 0" range="-3.14159 0.872665"/>
        <geom pos="0.110082 -0.006606 0.055268" type="mesh" contype="0" conaffinity="0" group="1" density="0" mesh="link1_1"/>
        <geom pos="0.110082 -0.006606 0.055268" type="mesh" mesh="link1_1"/>
        <body name="link2_1" pos="0 0.035617 -0.01">
          <inertial pos="2.2 0.0573721 0.00951152" quat="0.5 0.5 -0.5 0.5" mass="0.113212" diaginertia="0.00013 0.000125 4.4e-05"/>
          <joint name="joint_2" pos="0 0 0" axis="0 0 -1" range="-1.5708 1.5708"/>
          <geom pos="0.110082 -0.042223 0.065268" type="mesh" contype="0" conaffinity="0" group="1" density="0" mesh="link2_1"/>
          <geom pos="0.110082 -0.042223 0.065268" type="mesh" mesh="link2_1"/>
          <body name="link3_1" pos="0 0.0895 0.009">
            <inertial pos="-9.20403e-06 0.0280444 0.00865238" quat="0.98602 -0.166629 0 0" mass="0.140493" diaginertia="0.000123 0.00011361 5.23895e-05"/>
            <joint name="joint_3" pos="0 0 0" axis="0 -1 0"/>
            <geom pos="0.110082 -0.131723 0.055768" type="mesh" contype="0" conaffinity="0" group="1" density="0" mesh="link3_1"/>
            <geom pos="0.110082 -0.131723 0.055768" type="mesh" mesh="link3_1"/>
            <!--
            <body name="link4_1" pos="0 0.035618 -0.01">
              <inertial pos="2.36187e-05 0.0520203 0.0095084" quat="0.5 0.5 -0.5 0.5" mass="0.0941925" diaginertia="0.000106 0.0001 2.7e-05"/>
              <joint name="joint_4" pos="0 0 0" axis="0 0 -1"/>
              <geom pos="0.110082 -0.167341 0.065768" type="mesh" contype="0" conaffinity="0" group="1" density="0" mesh="link4_1"/>
              <geom pos="0.110082 -0.167341 0.065768" type="mesh" mesh="link4_1"/>
              <body name="link5_1" pos="0 0.0895 0.0095">
                <inertial pos="7.91086e-05 0.030031 0.0159086" quat="0.979515 -0.201372 0 0" mass="0.093482" diaginertia="7e-05 6.42931e-05 3.67069e-05"/>
                <joint name="joint_5" pos="0 0 0" axis="0 -1 0"/>
                <geom pos="0.110082 -0.256841 0.056268" type="mesh" contype="0" conaffinity="0" group="1" density="0" mesh="link5_1"/>
                <geom pos="0.110082 -0.256841 0.056268" type="mesh" mesh="link5_1"/>
                -->
                <!-- ================== GRIPPER ====================== -->
                <!--
                <body name="gripper" pos="0 0.025 0" euler="-1.57 0 0">
                  <inertial pos="0.000565176 0.0606526 0.0113399" quat="0.419041 0.436542 -0.586477 0.538405" mass="0.0992864" diaginertia="0.000174911 0.000171846 2.92432e-05"/>
                  <joint name="joint_6" pos="0 0 0" axis="0 0 -1" range="-1.91986 1.91986"/>
                  <geom pos="0 0 0" type="mesh" contype="0" conaffinity="0" group="1" density="0" mesh="gripper"/>
                  <geom pos="0 0 0" type="mesh" mesh="gripper"/>
                  <body name="finger_1a" pos="0.02165 -0.019744 0.11291">
                    <inertial pos="-0.00157739 -0.00535918 0.0147248" mass="0.00261935" diaginertia="3.33334e-06 3.33334e-06 3.33334e-06"/>
                    <joint name="F1J1" pos="0 0 0" axis="1 0 0" stiffness="0"/>
                    <geom pos="-0.02165 0.019744 -0.11291" type="mesh" contype="0" conaffinity="0" group="1" density="0" mesh="finger_1a"/>
                    <geom pos="-0.02165 0.019744 -0.11291" type="mesh" mesh="finger_1a"/>
                    <body name="finger_1b" pos="5e-05 -0.009918 0.027251">
                      <inertial pos="-0.00150154 0.0059248 0.0102624" mass="0.00161827" diaginertia="3.33333e-06 3.33333e-06 3.33333e-06"/>
                      <joint name="F1J2" pos="0 0 0" axis="-1 0 0" stiffness="0" springref="0"/>
                      <geom pos="-0.0217 0.029662 -0.140161" type="mesh" contype="0" conaffinity="0" group="1" density="0" mesh="finger_1b"/>
                      <geom pos="-0.0217 0.029662 -0.140161" type="mesh" mesh="finger_1b"/>
                      <body name="finger_1c" pos="5e-05 0.0105 0.018186">
                        <inertial pos="-0.00170001 0.00811429 0.00295382" mass="0.000960393" diaginertia="3.33333e-06 3.33333e-06 3.33333e-06"/>
                        <joint name="F1J3" pos="0 0 0" axis="-1 0 0" stiffness="0" springref="0"/>
                        <geom pos="-0.02175 0.019162 -0.158347" type="mesh" contype="0" conaffinity="0" group="1" density="0" mesh="finger_1c"/>
                        <geom pos="-0.02175 0.019162 -0.158347" type="mesh" mesh="finger_1c"/>
                      </body>
                    </body>
                  </body>
                  <body name="finger_3a" pos="-0.02185 -0.019744 0.11291">
                    <inertial pos="0.00182261 -0.00535918 0.0147248" mass="0.00261935" diaginertia="3.33333e-06 3.33333e-06 3.33333e-06"/>
                    <joint name="F3J1" pos="0 0 0" axis="-1 0 0" stiffness="0"/>
                    <geom pos="0.02185 0.019744 -0.11291" type="mesh" contype="0" conaffinity="0" group="1" density="0" mesh="finger_3a"/>
                    <geom pos="0.02185 0.019744 -0.11291" type="mesh" mesh="finger_3a"/>
                    <body name="finger_3b" pos="-5e-05 -0.009918 0.027251">
                      <inertial pos="0.00189846 0.0059248 0.0102624" mass="0.00161827" diaginertia="3.33333e-06 3.33333e-06 3.33333e-06"/>
                      <joint name="F3J2" pos="0 0 0" axis="1 0 0" stiffness="0" springref="0"/>
                      <geom pos="0.0219 0.029662 -0.140161" type="mesh" contype="0" conaffinity="0" group="1" density="0" mesh="finger_3b"/>
                      <geom pos="0.0219 0.029662 -0.140161" type="mesh" mesh="finger_3b"/>
                      <body name="finger_3c" pos="-5e-05 0.0105 0.018186">
                        <inertial pos="0.00169999 0.00811429 0.00295382" mass="0.000960393" diaginertia="3.33333e-06 3.33333e-06 3.33333e-06"/>
                        <joint name="F3J3" pos="0 0 0" axis="1 0 0" stiffness="0" springref="0"/>
                        <geom pos="0.02195 0.019162 -0.158347" type="mesh" contype="0" conaffinity="0" group="1" density="0" mesh="finger_3c"/>
                        <geom pos="0.02195 0.019162 -0.158347" type="mesh" mesh="finger_3c"/>
                      </body>
                    </body>
                  </body>
                  <body name="finger_2a" pos="-0.00185 0.019256 0.11291">
                    <inertial pos="0.00182261 0.00535983 0.0147248" mass="0.00261931" diaginertia="3.33333e-06 3.33333e-06 3.33333e-06"/>
                    <joint name="F2J1" pos="0 0 0" axis="-1 0 0"/>
                    <geom pos="0.00185 -0.019256 -0.11291" type="mesh" contype="0" conaffinity="0" group="1" density="0" mesh="finger_2a"/>
                    <geom pos="0.00185 -0.019256 -0.11291" type="mesh" mesh="finger_2a"/>
                    <body name="finger_2b" pos="-5e-05 0.009919 0.027251">
                      <inertial pos="0.00189846 -0.00592523 0.0102624" mass="0.00161828" diaginertia="3.33333e-06 3.33333e-06 3.33333e-06"/>
                      <joint name="F2J2" pos="0 0 0" axis="1 0 0" stiffness="0" springref="0"/>
                      <geom pos="0.0019 -0.029175 -0.140161" type="mesh" contype="0" conaffinity="0" group="1" density="0" mesh="finger_2b"/>
                      <geom pos="0.0019 -0.029175 -0.140161" type="mesh" mesh="finger_2b"/>
                      <body name="finger_2c" pos="-5e-05 -0.0105 0.018186">
                        <inertial pos="0.00169999 -0.0081147 0.00295382" mass="0.000960393" diaginertia="3.33333e-06 3.33333e-06 3.33333e-06"/>
                        <joint name="F2J3" pos="0 0 0" axis="1 0 0" stiffness="0" springref="0"/>
                        <geom pos="0.00195 -0.018675 -0.158347" type="mesh" contype="0" conaffinity="0" group="1" density="0" mesh="finger_2c"/>
                        <geom pos="0.00195 -0.018675 -0.158347" type="mesh" mesh="finger_2c"/>
                      </body>
                    </body>
                  </body>
                </body>
                -->
                <!--
              </body>
            </body>
            -->
          </body>
        </body>
      </body>
    </body>
  </worldbody>


  <actuator>
    <velocity name="J1" joint="joint_1" kv="1" gear="1 0 0 0 0 0"/> 
    <velocity name="J2" joint="joint_2" kv="1"  gear="4 0 0 0 0 0"/> 
    <velocity name="J3" joint="joint_3" kv="1" gear="4 0 0 0 0 0"/> 
    <!--
    <velocity name="J4" joint="joint_4" kv="1" gear="1 0 0 0 0 0"/> 
    <velocity name="J5" joint="joint_5" kv="1" gear="1 0 0 0 0 0"/> 
    
    <velocity name="J6" joint="joint_6" kv="1" gear="4 0 0 0 0 0"/> 
    
    <velocity name="GJ1" joint="F1J1" kv="10" gear="0.001 0 0 0 0 0"/> 
    <velocity name="GJ2" joint="F2J1" kv="10"  gear="0.001 0 0 0 0 0"/> 
    <velocity name="GJ3" joint="F3J1" kv="10" gear="0.001 0 0 0 0 0"/> 
    -->
  </actuator>
</mujoco>
