<?xml version="1.0" ?>
<robot name="arm2v4" xmlns:xacro="http://www.ros.org/wiki/xacro">

<link name="${arm}link_1">
  <inertial>
    <origin xyz="0.000994555873334066 0.032192633992419506 0.034631373816010426" rpy="0 0 0"/>
    <mass value="0.14794989873959544"/>
    <inertia ixx="0.000146" iyy="0.000139" izz="6.1e-05" ixy="-0.0" iyz="-1.9e-05" ixz="-4e-06"/>
  </inertial>
  <visual>
    <origin xyz="-0.0551 -0.00635 -0.1101" rpy="0 0 0"/>
    <geometry>
      <mesh filename="package://arm2v4_description/meshes/link_1.stl" scale="0.01 0.01 0.01"/>
    </geometry>
    <material name="silver"/>
  </visual>
  <collision>
    <origin xyz="-0.0551 -0.00635 -0.1101" rpy="0 0 0"/>
    <geometry>
      <mesh filename="package://arm2v4_description/meshes/link_1.stl" scale="0.01 0.01 0.01"/>
    </geometry>
  </collision>
</link>

<link name="${arm}link_2">
  <inertial>
    <origin xyz="-4.2329454017026036e-05 0.04921562557214742 0.0030738533730362907" rpy="0 0 0"/>
    <mass value="0.08725155707785047"/>
    <inertia ixx="9.1e-05" iyy="2.6e-05" izz="9.6e-05" ixy="0.0" iyz="-0.0" ixz="0.0"/>
  </inertial>
  <visual>
    <origin xyz="-0.0731 -0.041967 -0.1101" rpy="0 0 0"/>
    <geometry>
      <mesh filename="package://arm2v4_description/meshes/link_2.stl" scale="0.01 0.01 0.01"/>
    </geometry>
    <material name="silver"/>
  </visual>
  <collision>
    <origin xyz="-0.0731 -0.041967 -0.1101" rpy="0 0 0"/>
    <geometry>
      <mesh filename="package://arm2v4_description/meshes/link_2.stl" scale="0.01 0.01 0.01"/>
    </geometry>
  </collision>
</link>

<link name="${arm}link_3">
  <inertial>
    <origin xyz="-1.3823380757296833e-05 0.03022438867696911 0.0200511494227781" rpy="0 0 0"/>
    <mass value="0.09108039665669564"/>
    <inertia ixx="7.1e-05" iyy="6.2e-05" izz="3.8e-05" ixy="0.0" iyz="-1.2e-05" ixz="0.0"/>
  </inertial>
  <visual>
    <origin xyz="-0.0551 -0.130967 -0.1101" rpy="0 0 0"/>
    <geometry>
      <mesh filename="package://arm2v4_description/meshes/link_3.stl" scale="0.01 0.01 0.01"/>
    </geometry>
    <material name="silver"/>
  </visual>
  <collision>
    <origin xyz="-0.0551 -0.130967 -0.1101" rpy="0 0 0"/>
    <geometry>
      <mesh filename="package://arm2v4_description/meshes/link_3.stl" scale="0.01 0.01 0.01"/>
    </geometry>
  </collision>
</link>

<link name="${arm}link_4">
  <inertial>
    <origin xyz="-4.232946611194832e-05 0.04912810644241655 0.0030738548296062526" rpy="0 0 0"/>
    <mass value="0.08725154796869071"/>
    <inertia ixx="9.1e-05" iyy="2.6e-05" izz="9.6e-05" ixy="-0.0" iyz="-0.0" ixz="0.0"/>
  </inertial>
  <visual>
    <origin xyz="-0.0731 -0.167585 -0.1101" rpy="0 0 0"/>
    <geometry>
      <mesh filename="package://arm2v4_description/meshes/link_4.stl" scale="0.01 0.01 0.01"/>
    </geometry>
    <material name="silver"/>
  </visual>
  <collision>
    <origin xyz="-0.0731 -0.167585 -0.1101" rpy="0 0 0"/>
    <geometry>
      <mesh filename="package://arm2v4_description/meshes/link_4.stl" scale="0.01 0.01 0.01"/>
    </geometry>
  </collision>
</link>

<link name="${arm}link_5">
  <inertial>
    <origin xyz="6.10956164850962e-05 0.029339323281606933 0.01790395437814605" rpy="0 0 0"/>
    <mass value="0.07748637354366847"/>
    <inertia ixx="6.5e-05" iyy="5.7e-05" izz="3.4e-05" ixy="-0.0" iyz="-1e-05" ixz="-0.0"/>
  </inertial>
  <visual>
    <origin xyz="-0.0551 -0.256585 -0.1101" rpy="0 0 0"/>
    <geometry>
      <mesh filename="package://arm2v4_description/meshes/link_5.stl" scale="0.01 0.01 0.01"/>
    </geometry>
    <material name="silver"/>
  </visual>
  <collision>
    <origin xyz="-0.0551 -0.256585 -0.1101" rpy="0 0 0"/>
    <geometry>
      <mesh filename="package://arm2v4_description/meshes/link_5.stl" scale="0.01 0.01 0.01"/>
    </geometry>
  </collision>
</link>

<link name="${arm}link_6">
  <inertial>
    <origin xyz="6.94042323612365e-10 0.04917111509824407 0.0030728246091055456" rpy="0 0 0"/>
    <mass value="0.08703493547283644"/>
    <inertia ixx="9.1e-05" iyy="2.6e-05" izz="9.6e-05" ixy="0.0" iyz="-0.0" ixz="0.0"/>
  </inertial>
  <visual>
    <origin xyz="-0.0731 -0.293202 -0.1101" rpy="0 0 0"/>
    <geometry>
      <mesh filename="package://arm2v4_description/meshes/link_6.stl" scale="0.01 0.01 0.01"/>
    </geometry>
    <material name="silver"/>
  </visual>
  <collision>
    <origin xyz="-0.0731 -0.293202 -0.1101" rpy="0 0 0"/>
    <geometry>
      <mesh filename="package://arm2v4_description/meshes/link_6.stl" scale="0.01 0.01 0.01"/>
    </geometry>
  </collision>
</link>


<link name="${arm}gripper">
  <inertial>
    <origin xyz="-7.99617922246049e-05 -9.373301345926424e-05 0.022688831485682622" rpy="0 0 0"/>
    <mass value="0.06230882557508056"/>
    <inertia ixx="2e-05" iyy="2e-05" izz="1.8e-05" ixy="0.0" iyz="-0.0" ixz="0.0"/>
  </inertial>
  <visual>
    <origin xyz="-0.0551 -0.370702 -0.1101" rpy="0 0 0"/>
    <geometry>
      <mesh filename="package://arm2v4_description/meshes/gripper_base.stl" scale="0.01 0.01 0.01"/>
    </geometry>
    <material name="silver"/>
  </visual>
  <collision>
    <origin xyz="-0.0551 -0.370702 -0.1101" rpy="0 0 0"/>
    <geometry>
      <mesh filename="package://arm2v4_description/meshes/gripper_base.stl" scale="0.01 0.01 0.01"/>
    </geometry>
  </collision>
</link>

<link name="${arm}finger_1">
  <inertial>
    <origin xyz="-0.008642610431029825 -0.0223485533956419 0.01797350009267279" rpy="0 0 0"/>
    <mass value="0.00589987703289726"/>
    <inertia ixx="2e-06" iyy="1e-06" izz="1e-06" ixy="-0.0" iyz="1e-06" ixz="0.0"/>
  </inertial>
  <visual>
    <origin xyz="-0.005959 0.022452 -0.054853" rpy="0 0 0"/>
    <geometry>
      <mesh filename="package://arm2v4_description/meshes/finger_1.stl" scale="0.01 0.01 0.01"/>
    </geometry>
    <material name="silver"/>
  </visual>
  <collision>
    <origin xyz="-0.005959 0.022452 -0.054853" rpy="0 0 0"/>
    <geometry>
      <mesh filename="package://arm2v4_description/meshes/finger_1.stl" scale="0.01 0.01 0.01"/>
    </geometry>
  </collision>
</link>


<link name="${arm}finger_2">
  <inertial>
    <origin xyz="-0.023075113605405432 0.003290870425902617 0.016944927949491317" rpy="0 0 0"/>
    <mass value="0.005899814079558049"/>
    <inertia ixx="1e-06" iyy="2e-06" izz="1e-06" ixy="-0.0" iyz="0.0" ixz="1e-06"/>
  </inertial>
  <visual>
    <origin xyz="0.023955 0.005611 -0.053852" rpy="0 0 0"/>
    <geometry>
      <mesh filename="package://arm2v4_description/meshes/finger_2.stl" scale="0.01 0.01 0.01"/>
    </geometry>
    <material name="silver"/>
  </visual>
  <collision>
    <origin xyz="0.023955 0.005611 -0.053852" rpy="0 0 0"/>
    <geometry>
      <mesh filename="package://arm2v4_description/meshes/finger_2.stl" scale="0.01 0.01 0.01"/>
    </geometry>
  </collision>
</link>

<link name="${arm}finger_3">
  <inertial>
    <origin xyz="0.008090867314456025 0.02343237115984798 0.016811323538146863" rpy="0 0 0"/>
    <mass value="0.005899939849310272"/>
    <inertia ixx="2e-06" iyy="1e-06" izz="1e-06" ixy="-0.0" iyz="-1e-06" ixz="0.0"/>
  </inertial>
  <visual>
    <origin xyz="0.007093 -0.024302 -0.053188" rpy="0 0 0"/>
    <geometry>
      <mesh filename="package://arm2v4_description/meshes/finger_3.stl" scale="0.01 0.01 0.01"/>
    </geometry>
    <material name="silver"/>
  </visual>
  <collision>
    <origin xyz="0.007093 -0.024302 -0.053188" rpy="0 0 0"/>
    <geometry>
      <mesh filename="package://arm2v4_description/meshes/finger_3.stl" scale="0.01 0.01 0.01"/>
    </geometry>
  </collision>
</link>

<link name="${arm}finger_4">
  <inertial>
    <origin xyz="0.022522095224022032 -0.0022060565296590394 0.017840959663214417" rpy="0 0 0"/>
    <mass value="0.005899858594402945"/>
    <inertia ixx="1e-06" iyy="2e-06" izz="1e-06" ixy="-0.0" iyz="-0.0" ixz="-1e-06"/>
  </inertial>
  <visual>
    <origin xyz="-0.022822 -0.00746 -0.054188" rpy="0 0 0"/>
    <geometry>
      <mesh filename="package://arm2v4_description/meshes/finger_4.stl" scale="0.01 0.01 0.01"/>
    </geometry>
    <material name="silver"/>
  </visual>
  <collision>
    <origin xyz="-0.022822 -0.00746 -0.054188" rpy="0 0 0"/>
    <geometry>
      <mesh filename="package://arm2v4_description/meshes/finger_4.stl" scale="0.01 0.01 0.01"/>
    </geometry>
  </collision>
</link>

<joint name="${arm}joint_1" type="continuous">
  <xacro:if value="${namespace == 'ARM1'}">
    <xacro:if value="${arm == ''}">
      <origin xyz="-0.1101 0.007 -0.0551" rpy="0 1.57 0"/>
    </xacro:if>
    <xacro:unless value="${arm == ''}">
      <origin xyz="0.0551 0.007 0.1101" rpy="0 0 0"/>
    </xacro:unless>
  </xacro:if>

  <xacro:if value="${namespace == 'ARM2'}">
    <xacro:if value="${arm == ''}">
      <origin xyz="0.0551 0.007 0.1101" rpy="0 0 0"/>
    </xacro:if>
    <xacro:unless value="${arm == ''}">
      <origin xyz="-0.1101 0.007 -0.0551" rpy="0 1.57 0"/>
    </xacro:unless>
  </xacro:if>





  <parent link="base_link"/>
  <child link="${arm}link_1"/>
  <axis xyz="-0.0 -1.0 0.0"/>
  <!--<limit upper="3.141593" lower="-3.141593" effort="100" velocity="100"/>-->
</joint>

<joint name="${arm}joint_2" type="revolute">
  <origin xyz="0.018 0.035617 0" rpy="0 0 0"/>
  <parent link="${arm}link_1"/>
  <child link="${arm}link_2"/>
  <axis xyz="-1.0 0.0 0.0"/>
  <limit upper="1.570796" lower="-1.570796" effort="100" velocity="100"/>
</joint>

<joint name="${arm}joint_3" type="continuous">
  <origin xyz="-0.018 0.089 0" rpy="0 0 0"/>
  <parent link="${arm}link_2"/>
  <child link="${arm}link_3"/>
  <axis xyz="-0.0 1.0 -0.0"/>
  <!--<limit upper="3.14" lower="-3.14" effort="100" velocity="100"/>-->
</joint>

<joint name="${arm}joint_4" type="revolute">
  <origin xyz="0.018 0.036618 0" rpy="0 0 0"/>
  <parent link="${arm}link_3"/>
  <child link="${arm}link_4"/>
  <axis xyz="-1.0 -0.0 0.0"/>
  <limit upper="1.919862" lower="-1.919862" effort="100" velocity="100"/>
</joint>

<joint name="${arm}joint_5" type="continuous">
  <origin xyz="-0.018 0.089 0" rpy="0 0 0"/>
  <parent link="${arm}link_4"/>
  <child link="${arm}link_5"/>
  <axis xyz="-0.0 1.0 -0.0"/>
  <!--<limit upper="3.14" lower="-3.14" effort="100" velocity="100"/>-->
</joint>

<joint name="${arm}joint_6" type="revolute">
  <origin xyz="0.018 0.036617 0" rpy="0 0 0"/>
  <parent link="${arm}link_5"/>
  <child link="${arm}link_6"/>
  <axis xyz="-1.0 -0.0 0.0"/>
  <limit upper="1.919862" lower="-1.919862" effort="100" velocity="100"/>
</joint>

<joint name="${arm}joint_7" type="continuous">
 <!-- <origin xyz="0.0 0.089 0.003" rpy="0 0 0"/>-->
  <origin xyz="-0.018 0.0775 0" rpy="0 0 0"/>
  <parent link="${arm}link_6"/>
  <child link="${arm}gripper"/>
  <axis xyz="-0.0 1.0 0.0"/>
  <!--<limit upper="3.14" lower="-3.14" effort="100" velocity="100"/>-->
</joint>


<joint name="${arm}gripper_joint_1" type="revolute">
  <origin xyz="0.006125 0.0535 0.0235" rpy="-1.53 0 0"/>
  <parent link="${arm}gripper"/>
  <child link="${arm}finger_1"/>
  <axis xyz="0.999727 0.017623 0.01534"/>
  <limit upper="0.0" lower="-1.134464" effort="100" velocity="100"/>
</joint>


<joint name="${arm}gripper_joint_2" type="revolute">
  <origin xyz="-0.0235 0.0535 0.006125" rpy="-1.53 0 0"/>
  <parent link="${arm}gripper"/>
  <child link="${arm}finger_2"/>
  <axis xyz="0.017134 -0.999359 0.031436"/>
  <limit upper="0.0" lower="-1.134464" effort="100" velocity="100"/>
</joint>

<joint name="${arm}gripper_joint_3" type="revolute">
  <origin xyz="-0.006125 0.0535 -0.0235" rpy="-1.53 0 0"/>
  <parent link="${arm}gripper"/>
  <child link="${arm}finger_3"/>
  <axis xyz="-0.999727 -0.017623 -0.01534"/>
  <limit upper="0.0" lower="-1.134464" effort="100" velocity="100"/>
</joint>

<joint name="${arm}gripper_joint_4" type="revolute">
  <origin xyz="0.0235 0.0535 -0.006125" rpy="-1.53 0 0"/>
  <parent link="${arm}gripper"/>
  <child link="${arm}finger_4"/>
  <axis xyz="-0.017134 0.999359 -0.031436"/>
  <limit upper="0.0" lower="-1.134464" effort="100" velocity="100"/>
</joint>

</robot>
