<?xml version="1.0" ?>
<robot name="v5_gripper" xmlns:xacro="http://www.ros.org/wiki/xacro">

<xacro:include filename="$(find arm2v4_description)/urdf/materials.xacro" />
<xacro:include filename="$(find arm2v4_description)/urdf/v5_gripper.trans" />
<xacro:include filename="$(find arm2v4_description)/urdf/v5_gripper.gazebo" />

<link name="gripper_base">
  <inertial>
    <origin xyz="-7.99617922246049e-05 -9.373301345926424e-05 0.022688831485682622" rpy="0 0 0"/>
    <mass value="0.06230882557508056"/>
    <inertia ixx="2e-05" iyy="2e-05" izz="1.8e-05" ixy="0.0" iyz="-0.0" ixz="0.0"/>
  </inertial>
  <visual>
    <origin xyz="0 0 0" rpy="0 0 0"/>
    <geometry>
      <mesh filename="package://arm2v4_description/meshes/gripper_base.stl" scale="0.01 0.01 0.01"/>
    </geometry>
    <material name="silver"/>
  </visual>
  <collision>
    <origin xyz="0 0 0" rpy="0 0 0"/>
    <geometry>
      <mesh filename="package://arm2v4_description/meshes/gripper_base.stl" scale="0.01 0.01 0.01"/>
    </geometry>
  </collision>
</link>

<link name="finger_1">
  <inertial>
    <origin xyz="-0.008642610431029825 -0.0223485533956419 0.01797350009267279" rpy="0 0 0"/>
    <mass value="0.00589987703289726"/>
    <inertia ixx="2e-06" iyy="1e-06" izz="1e-06" ixy="-0.0" iyz="1e-06" ixz="0.0"/>
  </inertial>
  <visual>
    <origin xyz="-0.005959 0.022452 -0.054853" rpy="0 0 0"/>
    <geometry>
      <mesh filename="package://arm2v4_description/meshes/finger_1.stl" scale="0.01 0.01 0.01"/>
    </geometry>
    <material name="silver"/>
  </visual>
  <collision>
    <origin xyz="-0.005959 0.022452 -0.054853" rpy="0 0 0"/>
    <geometry>
      <mesh filename="package://arm2v4_description/meshes/finger_1.stl" scale="0.01 0.01 0.01"/>
    </geometry>
  </collision>
</link>


<link name="finger_2">
  <inertial>
    <origin xyz="-0.023075113605405432 0.003290870425902617 0.016944927949491317" rpy="0 0 0"/>
    <mass value="0.005899814079558049"/>
    <inertia ixx="1e-06" iyy="2e-06" izz="1e-06" ixy="-0.0" iyz="0.0" ixz="1e-06"/>
  </inertial>
  <visual>
    <origin xyz="0.023955 0.005611 -0.053852" rpy="0 0 0"/>
    <geometry>
      <mesh filename="package://arm2v4_description/meshes/finger_2.stl" scale="0.01 0.01 0.01"/>
    </geometry>
    <material name="silver"/>
  </visual>
  <collision>
    <origin xyz="0.023955 0.005611 -0.053852" rpy="0 0 0"/>
    <geometry>
      <mesh filename="package://arm2v4_description/meshes/finger_2.stl" scale="0.01 0.01 0.01"/>
    </geometry>
  </collision>
</link>

<link name="finger_3">
  <inertial>
    <origin xyz="0.008090867314456025 0.02343237115984798 0.016811323538146863" rpy="0 0 0"/>
    <mass value="0.005899939849310272"/>
    <inertia ixx="2e-06" iyy="1e-06" izz="1e-06" ixy="-0.0" iyz="-1e-06" ixz="0.0"/>
  </inertial>
  <visual>
    <origin xyz="0.007093 -0.024302 -0.053188" rpy="0 0 0"/>
    <geometry>
      <mesh filename="package://arm2v4_description/meshes/finger_3.stl" scale="0.01 0.01 0.01"/>
    </geometry>
    <material name="silver"/>
  </visual>
  <collision>
    <origin xyz="0.007093 -0.024302 -0.053188" rpy="0 0 0"/>
    <geometry>
      <mesh filename="package://arm2v4_description/meshes/finger_3.stl" scale="0.01 0.01 0.01"/>
    </geometry>
  </collision>
</link>

<link name="finger_4">
  <inertial>
    <origin xyz="0.022522095224022032 -0.0022060565296590394 0.017840959663214417" rpy="0 0 0"/>
    <mass value="0.005899858594402945"/>
    <inertia ixx="1e-06" iyy="2e-06" izz="1e-06" ixy="-0.0" iyz="-0.0" ixz="-1e-06"/>
  </inertial>
  <visual>
    <origin xyz="-0.022822 -0.00746 -0.054188" rpy="0 0 0"/>
    <geometry>
      <mesh filename="package://arm2v4_description/meshes/finger_4.stl" scale="0.01 0.01 0.01"/>
    </geometry>
    <material name="silver"/>
  </visual>
  <collision>
    <origin xyz="-0.022822 -0.00746 -0.054188" rpy="0 0 0"/>
    <geometry>
      <mesh filename="package://arm2v4_description/meshes/finger_4.stl" scale="0.01 0.01 0.01"/>
    </geometry>
  </collision>
</link>


<joint name="gripper_joint_1" type="revolute">
  <origin xyz="0.005959 -0.022452 0.054853" rpy="0 0 0"/>
  <parent link="base_link"/>
  <child link="finger_1"/>
  <axis xyz="0.999727 0.017623 0.01534"/>
  <limit upper="0.0" lower="-1.134464" effort="100" velocity="100"/>
</joint>


<joint name="gripper_joint_2" type="revolute">
  <origin xyz="-0.023955 -0.005611 0.053852" rpy="0 0 0"/>
  <parent link="base_link"/>
  <child link="finger_2"/>
  <axis xyz="0.017134 -0.999359 0.031436"/>
  <limit upper="0.0" lower="-1.134464" effort="100" velocity="100"/>
</joint>

<joint name="gripper_joint_3" type="revolute">
  <origin xyz="-0.007093 0.024302 0.053188" rpy="0 0 0"/>
  <parent link="base_link"/>
  <child link="finger_3"/>
  <axis xyz="-0.999727 -0.017623 -0.01534"/>
  <limit upper="0.0" lower="-1.134464" effort="100" velocity="100"/>
</joint>

<joint name="gripper_joint_4" type="revolute">
  <origin xyz="0.022822 0.00746 0.054188" rpy="0 0 0"/>
  <parent link="base_link"/>
  <child link="finger_4"/>
  <axis xyz="-0.017134 0.999359 -0.031436"/>
  <limit upper="0.0" lower="-1.134464" effort="100" velocity="100"/>
</joint>

</robot>
