<robot name="v5_gripper">
	<link name="base_link">
		<inertial>
			<origin rpy="0 0 0" xyz="-7.99617922246049e-05 -9.373301345926424e-05 0.022688831485682622" />
			<mass value="0.06230882557508056" />
			<inertia ixx="2e-05" ixy="0.0" ixz="0.0" iyy="2e-05" iyz="-0.0" izz="1.8e-05" />
		</inertial>
		<visual>
			<origin rpy="0 0 0" xyz="0 0 0" />
			<geometry>
				<mesh filename="package://v5_gripper_description/meshes/base_link.stl" scale="0.001 0.001 0.001" />
			</geometry>
			<material name="silver" />
		</visual>
		<collision>
			<origin rpy="0 0 0" xyz="0 0 0" />
			<geometry>
				<mesh filename="package://v5_gripper_description/meshes/base_link.stl" scale="0.001 0.001 0.001" />
			</geometry>
		</collision>
	</link>
	<link name="finger_1_1">
		<inertial>
			<origin rpy="0 0 0" xyz="-0.008642610431029825 -0.0223485533956419 0.01797350009267279" />
			<mass value="0.00589987703289726" />
			<inertia ixx="2e-06" ixy="-0.0" ixz="0.0" iyy="1e-06" iyz="1e-06" izz="1e-06" />
		</inertial>
		<visual>
			<origin rpy="0 0 0" xyz="-0.005959 0.022452 -0.054853" />
			<geometry>
				<mesh filename="package://v5_gripper_description/meshes/finger_1_1.stl" scale="0.001 0.001 0.001" />
			</geometry>
			<material name="silver" />
		</visual>
		<collision>
			<origin rpy="0 0 0" xyz="-0.005959 0.022452 -0.054853" />
			<geometry>
				<mesh filename="package://v5_gripper_description/meshes/finger_1_1.stl" scale="0.001 0.001 0.001" />
			</geometry>
		</collision>
	</link>
	<link name="finger_4_1">
		<inertial>
			<origin rpy="0 0 0" xyz="0.022522095224022032 -0.0022060565296590394 0.017840959663214417" />
			<mass value="0.005899858594402945" />
			<inertia ixx="1e-06" ixy="-0.0" ixz="-1e-06" iyy="2e-06" iyz="-0.0" izz="1e-06" />
		</inertial>
		<visual>
			<origin rpy="0 0 0" xyz="-0.022822 -0.00746 -0.054188" />
			<geometry>
				<mesh filename="package://v5_gripper_description/meshes/finger_4_1.stl" scale="0.001 0.001 0.001" />
			</geometry>
			<material name="silver" />
		</visual>
		<collision>
			<origin rpy="0 0 0" xyz="-0.022822 -0.00746 -0.054188" />
			<geometry>
				<mesh filename="package://v5_gripper_description/meshes/finger_4_1.stl" scale="0.001 0.001 0.001" />
			</geometry>
		</collision>
	</link>
	<link name="finger_3_1">
		<inertial>
			<origin rpy="0 0 0" xyz="0.008090867314456025 0.02343237115984798 0.016811323538146863" />
			<mass value="0.005899939849310272" />
			<inertia ixx="2e-06" ixy="-0.0" ixz="0.0" iyy="1e-06" iyz="-1e-06" izz="1e-06" />
		</inertial>
		<visual>
			<origin rpy="0 0 0" xyz="0.007093 -0.024302 -0.053188" />
			<geometry>
				<mesh filename="package://v5_gripper_description/meshes/finger_3_1.stl" scale="0.001 0.001 0.001" />
			</geometry>
			<material name="silver" />
		</visual>
		<collision>
			<origin rpy="0 0 0" xyz="0.007093 -0.024302 -0.053188" />
			<geometry>
				<mesh filename="package://v5_gripper_description/meshes/finger_3_1.stl" scale="0.001 0.001 0.001" />
			</geometry>
		</collision>
	</link>
	<link name="finger_2_1">
		<inertial>
			<origin rpy="0 0 0" xyz="-0.023075113605405432 0.003290870425902617 0.016944927949491317" />
			<mass value="0.005899814079558049" />
			<inertia ixx="1e-06" ixy="-0.0" ixz="1e-06" iyy="2e-06" iyz="0.0" izz="1e-06" />
		</inertial>
		<visual>
			<origin rpy="0 0 0" xyz="0.023955 0.005611 -0.053852" />
			<geometry>
				<mesh filename="package://v5_gripper_description/meshes/finger_2_1.stl" scale="0.001 0.001 0.001" />
			</geometry>
			<material name="silver" />
		</visual>
		<collision>
			<origin rpy="0 0 0" xyz="0.023955 0.005611 -0.053852" />
			<geometry>
				<mesh filename="package://v5_gripper_description/meshes/finger_2_1.stl" scale="0.001 0.001 0.001" />
			</geometry>
		</collision>
	</link>
	<joint name="Revolute 5" type="revolute">
		<origin rpy="0 0 0" xyz="0.005959 -0.022452 0.054853" />
		<parent link="base_link" />
		<child link="finger_1_1" />
		<axis xyz="0.999727 0.017623 0.01534" />
		<limit effort="100" lower="-1.134464" upper="0.0" velocity="100" />
	</joint>
	<joint name="Revolute 6" type="revolute">
		<origin rpy="0 0 0" xyz="0.022822 0.00746 0.054188" />
		<parent link="base_link" />
		<child link="finger_4_1" />
		<axis xyz="-0.017134 0.999359 -0.031436" />
		<limit effort="100" lower="-1.134464" upper="0.0" velocity="100" />
	</joint>
	<joint name="Revolute 7" type="revolute">
		<origin rpy="0 0 0" xyz="-0.007093 0.024302 0.053188" />
		<parent link="base_link" />
		<child link="finger_3_1" />
		<axis xyz="-0.999727 -0.017623 -0.01534" />
		<limit effort="100" lower="-1.134464" upper="0.0" velocity="100" />
	</joint>
	<joint name="Revolute 8" type="revolute">
		<origin rpy="0 0 0" xyz="-0.023955 -0.005611 0.053852" />
		<parent link="base_link" />
		<child link="finger_2_1" />
		<axis xyz="0.017134 -0.999359 0.031436" />
		<limit effort="100" lower="-1.134464" upper="0.0" velocity="100" />
	</joint>
	<mujoco>
		<compiler balanceinertia="true" discardvisual="false" meshdir="../meshes" />
		<asset>
			<material name="grid" reflectance="0.2" texrepeat="1 1" texture="grid" texuniform="true" />
		</asset>
	</mujoco>
</robot>